<?xml version="1.0" encoding="utf-8"?>

<mujoco model="pull_object">
    <body name="pull_object" pos="0.0 -0.55 0.82" euler ="0 0 3.141592">
        <joint type="slide" range="-0.2 0.2" axis="1 0 0" name="obj_slidex" pos="0 0 0" damping="1" limited="true"/>
        <joint type="slide" range="-0.2 0.2" axis="0 1 0" name="obj_slidey" pos="0 0 0" damping="1" limited="true"/>
        <!-- <inertial mass="0.001" pos="0 0 0" diaginertia="100000 100000 100000"/> -->
        <!-- <geom conaffinity="1" contype="1" mass="0.1" rgba="0 0 1 1" size="0.04 0.04 0.06" type="box" solimp="0.99 0.99 0.01" solref="0.01 1"/>
        <geom type="box" pos="0 -0.095 0" size="0.005 0.005 0.04" rgba="0 0 0 1" contype="1" conaffinity="1" name="handle" solimp="0.99 0.99 0.01" solref="0.01 1"/>
        <geom type="box" pos="0 -0.065 0.035" size="0.005 0.025 0.005" rgba="0 0 0 1" contype="1" conaffinity="1" solimp="0.99 0.99 0.01" solref="0.01 1"/>
        <geom type="box" pos="0 -0.065 -0.035" size="0.005 0.025 0.005" rgba="0 0 0 1" contype="1" conaffinity="1" solimp="0.99 0.99 0.01" solref="0.01 1"/>
        <site name="insertion" pos="0 -0.06 0" size="0.001" rgba="1 0 0 1"/> -->
        <geom conaffinity="1" contype="1" mass="0.1" rgba="0 0 1 1" size="0.05 0.05 0.08" type="box" solimp="0.99 0.99 0.01" solref="0.01 1"/>
        <geom type="box" pos="0 -0.135 0" size="0.005 0.005 0.06" rgba="0 0 0 1" contype="1" conaffinity="1" name="handle" solimp="0.99 0.99 0.01" solref="0.01 1"/>
        <!-- <geom type="box" pos="0 -0.09 0.055" size="0.005 0.04 0.005" rgba="0 0 0 1" contype="1" conaffinity="1" solimp="0.99 0.99 0.01" solref="0.01 1"/> -->
        <geom type="box" pos="0 -0.09 -0.055" size="0.005 0.04 0.005" rgba="0 0 0 1" contype="1" conaffinity="1" solimp="0.99 0.99 0.01" solref="0.01 1"/>
        <site name="insertion" pos="0 -0.09 0" size="0.01" rgba="1 0 0 1"/>
    </body>
</mujoco>